Workbook

Sheet Лист_1
B2: Вид номенклатуры (для расчета графика производства) | C2: Код | D2: Номенклатура | E2: Клиент | F2: Номер | G2: Заказ | H2: График оплаты | I2: Менеджер | J2: Дата заказа | K2: Дата согласования | L2: Остаток на складе | M2: В резерве | N2: К обеспечению | O2: Доступно | P2: В производстве | Q2: 1 | R2: 26.03.2026 | S2: 27.03.2026 | T2: 30.03.2026 | U2: 31.03.2026 | V2: 01.04.2026 | W2: 02.04.2026 | X2: 03.04.2026
B3: БЛОКИ АВАРИЙНОГО ПИТАНИЯ (100 max) | C3: ЦБ000017576 | D3: БАП комбинированный выносной CSVT D-CC 1h-36W-350mA-G-03-E-1 | E3: ТД ЭЛЕКТРОТЕХМОНТАЖ, АО | F3: 00ЦБ-002640 | G3: Заказ клиента 00ЦБ-002640 от 20.03.2026 16:51:49 | H3: Рассрочка 60 к.дней | I3: Максимов А. И. | J3: 20.03.2026 16:51:49 | K3: 23.03.2026 | L3: 5 | N3: 85 | P3: 85 | Q3: {=_xlfn._xlws.FILTER([1]График!$R$3:$R$89,([1]График!$F$3:$F$89=F3)*([1]График!$C$3:$C$89=C3))} -> #VALUE! | S3: 85
B4: БЛОКИ АВАРИЙНОГО ПИТАНИЯ (100 max) | C4: ЦБ000017576 | D4: БАП комбинированный выносной CSVT D-CC 1h-36W-350mA-G-03-E-1 | E4: ТрансИнжиниринг, ООО | F4: 00ЦБ-001835 | G4: Заказ клиента 00ЦБ-001835 от 27.02.2026 13:30:30 | H4: Предоплата 100% до передачи в производство | I4: Егиазаров А | J4: 27.02.2026 13:30:30 | K4: 05.03.2026 | L4: 5 | M4: 3 | N4: 15 | P4: 15 | Q4: {=_xlfn._xlws.FILTER([1]График!$R$3:$R$89,([1]График!$F$3:$F$89=F4)*([1]График!$C$3:$C$89=C4))} -> #VALUE! | U4: 15
B5: БЛОКИ АВАРИЙНОГО ПИТАНИЯ (100 max) | C5: ЦБ000017577 | D5: БАП комбинированный выносной CSVT D-CC 3h-36W-350mA-G-03-E-1 | E5: ЛИНИЯ СВЕТА, ООО | F5: 00ЦБ-001636 | G5: Заказ клиента 00ЦБ-001636 от 24.02.2026 9:32:25 | H5: Предоплата 100% | I5: Дивавина О.Д. | J5: 24.02.2026 9:32:25 | K5: 27.02.2026 | N5: 200 | P5: 200 | Q5: {=_xlfn._xlws.FILTER([1]График!$R$3:$R$89,([1]График!$F$3:$F$89=F5)*([1]График!$C$3:$C$89=C5))} -> #VALUE! | R5: 100
B6: КОМПЛЕКТЫ ДЛЯ СВЕТИЛЬНИКОВ (500 max) | C6: ЦБ-00012388 | D6: Пластина для ЛПП Слим Терра | E6: ТЕРРА ТД, ООО | F6: 00ЦБ-002634 | G6: Заказ клиента 00ЦБ-002634 от 20.03.2026 15:26:49 | H6: Предоплата 100% | I6: Дивавина О.Д. | J6: 20.03.2026 15:26:49 | K6: 23.03.2026 | N6: 70 | P6: 70 | Q6: {=_xlfn._xlws.FILTER([1]График!$R$3:$R$89,([1]График!$F$3:$F$89=F6)*([1]График!$C$3:$C$89=C6))} -> #VALUE!
B7: КОМПЛЕКТЫ ДЛЯ СВЕТИЛЬНИКОВ (500 max) | C7: ЦБ-00012388 | D7: Пластина для ЛПП Слим Терра | E7: ТЕРРА ТД, ООО | F7: 00ЦБ-002713 | G7: Заказ клиента 00ЦБ-002713 от 23.03.2026 16:02:38 | H7: Предоплата 100% | I7: Дивавина О.Д. | J7: 23.03.2026 16:02:38 | K7: 24.03.2026 | N7: 20 | P7: 20 | Q7: {=_xlfn._xlws.FILTER([1]График!$R$3:$R$89,([1]График!$F$3:$F$89=F7)*([1]График!$C$3:$C$89=C7))} -> #VALUE!
B8: КОМПЛЕКТЫ ДЛЯ СВЕТИЛЬНИКОВ (500 max) | C8: ЦБ-00012391 | D8: Пластина для ЛПП Айсберг Терра | E8: ТЕРРА ТД, ООО | F8: 00ЦБ-002713 | G8: Заказ клиента 00ЦБ-002713 от 23.03.2026 16:02:38 | H8: Предоплата 100% | I8: Дивавина О.Д. | J8: 23.03.2026 16:02:38 | K8: 24.03.2026 | L8: 42.83 | N8: 20 | P8: 20 | Q8: {=_xlfn._xlws.FILTER([1]График!$R$3:$R$89,([1]График!$F$3:$F$89=F8)*([1]График!$C$3:$C$89=C8))} -> #VALUE!
B9: КОМПЛЕКТЫ ДЛЯ СВЕТИЛЬНИКОВ (500 max) | C9: ЦБ-00012391 | D9: Пластина для ЛПП Айсберг Терра | E9: ТЕРРА ТД, ООО | F9: 00ЦБ-002698 | G9: Заказ клиента 00ЦБ-002698 от 23.03.2026 14:01:53 | H9: Предоплата 100% до передачи в производство | I9: Дивавина О.Д. | J9: 23.03.2026 14:01:53 | K9: 24.03.2026 | L9: 42.83 | N9: 12 | P9: 12 | Q9: {=_xlfn._xlws.FILTER([1]График!$R$3:$R$89,([1]График!$F$3:$F$89=F9)*([1]График!$C$3:$C$89=C9))} -> #VALUE!
B10: КОМПЛЕКТЫ ДЛЯ СВЕТИЛЬНИКОВ (500 max) | C10: ЦБ000012440 | D10: CSVT 2 пружины SPRING-VOLGA /FLORA | E10: ТД ЭЛЕКТРОТЕХМОНТАЖ, АО | F10: 00ЦБ-002576 | G10: Заказ клиента 00ЦБ-002576 от 19.03.2026 15:17:13 | H10: Рассрочка 60 к.дней | I10: Потапова Елена | J10: 19.03.2026 15:17:13 | K10: 19.03.2026 | N10: 70 | P10: 70 | Q10: {=_xlfn._xlws.FILTER([1]График!$R$3:$R$89,([1]График!$F$3:$F$89=F10)*([1]График!$C$3:$C$89=C10))} -> #VALUE!
B11: КОМПЛЕКТЫ ДЛЯ СВЕТИЛЬНИКОВ (500 max) | C11: ЦБ000012440 | D11: CSVT 2 пружины SPRING-VOLGA /FLORA | E11: ТД ЭЛЕКТРОТЕХМОНТАЖ, АО | F11: 00ЦБ-002597 | G11: Заказ клиента 00ЦБ-002597 от 20.03.2026 9:59:51 | H11: Рассрочка 60 к.дней | I11: Яворик Ю.В. | J11: 20.03.2026 9:59:51 | K11: 20.03.2026 | N11: 13 | P11: 13 | Q11: {=_xlfn._xlws.FILTER([1]График!$R$3:$R$89,([1]График!$F$3:$F$89=F11)*([1]График!$C$3:$C$89=C11))} -> #VALUE!
B12: КОРПУСА SLIM (2000 max) | C12: ЦБ-00012270 | D12: Корпус светильника Slim/TRANSPARENT (IP65), ГУЛОВ | E12: Гулов М.В., ИП | F12: 00ЦБ-002688 | G12: Заказ клиента 00ЦБ-002688 от 23.03.2026 12:50:57 | H12: Предоплата 100% | I12: Дивавина О.Д. | J12: 23.03.2026 12:50:57 | K12: 24.03.2026 | N12: 300 | P12: 300 | Q12: {=_xlfn._xlws.FILTER([1]График!$R$3:$R$89,([1]График!$F$3:$F$89=F12)*([1]График!$C$3:$C$89=C12))} -> #VALUE!
B13: КОРПУСА SLIM (2000 max) | C13: ЦБ-00012299 | D13: Корпус светильника Slim/MILKY (IP65), АЛБ | E13: АЛБ, ООО | F13: 00ЦБ-002281 | G13: Заказ клиента 00ЦБ-002281 от 13.03.2026 9:06:05 | H13: Предоплата 30% до передачи в производство, до отгрузки 70% | I13: Куртеев Н.А. | J13: 13.03.2026 9:06:05 | K13: 22.03.2026 | N13: 50 | P13: 50 | Q13: {=_xlfn._xlws.FILTER([1]График!$R$3:$R$89,([1]График!$F$3:$F$89=F13)*([1]График!$C$3:$C$89=C13))} -> #VALUE!
B14: КОРПУСА АЙСБЕРГ (2000 max) | C14: РУ000006824 | D14: Плафон 2х36 Айсберг/TRANSPARENT (ГП) | E14: ТД ЭЛЕКТРОТЕХМОНТАЖ, АО | F14: 00ЦБ-002606 | G14: Заказ клиента 00ЦБ-002606 от 20.03.2026 10:55:41 | H14: Рассрочка 60 к.дней | I14: Кузнецова С. | J14: 20.03.2026 10:55:41 | K14: 20.03.2026 | N14: 40 | P14: 40 | Q14: {=_xlfn._xlws.FILTER([1]График!$R$3:$R$89,([1]График!$F$3:$F$89=F14)*([1]График!$C$3:$C$89=C14))} -> #VALUE!
B15: КОРПУСА АЙСБЕРГ (2000 max) | C15: ЦБ-00012238 | D15: Корпус светильника Айсберг/MILKY (IP65), ГАЗСНАБ | E15: ГАЗСНАБ, ООО | F15: 00ЦБ-001820 | G15: Заказ клиента 00ЦБ-001820 от 27.02.2026 11:29:34 | H15: Предоплата 100% | I15: Степанов Б.С. | J15: 27.02.2026 11:29:34 | K15: 20.03.2026 | N15: 1950 | P15: 1950 | Q15: {=_xlfn._xlws.FILTER([1]График!$R$3:$R$89,([1]График!$F$3:$F$89=F15)*([1]График!$C$3:$C$89=C15))} -> #VALUE! | R15: 514
B16: КОРПУСА АЙСБЕРГ (2000 max) | C16: ЦБ000019348 | D16: Корпус светильника Айсберг/MILKY (IP65) без мет пластины | E16: ТЕРРА ТД, ООО | F16: 00ЦБ-002578 | G16: Заказ клиента 00ЦБ-002578 от 19.03.2026 15:29:00 | H16: Предоплата 30% до передачи в производство, до отгрузки 70% | I16: Дивавина О.Д. | J16: 19.03.2026 15:29:00 | K16: 20.03.2026 | L16: 73.34 | N16: 12 | P16: 12 | Q16: {=_xlfn._xlws.FILTER([1]График!$R$3:$R$89,([1]График!$F$3:$F$89=F16)*([1]График!$C$3:$C$89=C16))} -> #VALUE!
B17: КОРПУСА АЙСБЕРГ (2000 max) | C17: ЦБ000019348 | D17: Корпус светильника Айсберг/MILKY (IP65) без мет пластины | E17: ТЕРРА ТД, ООО | F17: 00ЦБ-002713 | G17: Заказ клиента 00ЦБ-002713 от 23.03.2026 16:02:38 | H17: Предоплата 100% | I17: Дивавина О.Д. | J17: 23.03.2026 16:02:38 | K17: 24.03.2026 | L17: 73.33 | N17: 20 | P17: 20 | Q17: {=_xlfn._xlws.FILTER([1]График!$R$3:$R$89,([1]График!$F$3:$F$89=F17)*([1]График!$C$3:$C$89=C17))} -> #VALUE! | R17: 20
B18: КОРПУСА АЙСБЕРГ (2000 max) | C18: ЦБ000019348 | D18: Корпус светильника Айсберг/MILKY (IP65) без мет пластины | E18: ТЕРРА ТД, ООО | F18: 00ЦБ-002698 | G18: Заказ клиента 00ЦБ-002698 от 23.03.2026 14:01:53 | H18: Предоплата 100% до передачи в производство | I18: Дивавина О.Д. | J18: 23.03.2026 14:01:53 | K18: 24.03.2026 | L18: 73.33 | N18: 12 | P18: 12 | Q18: {=_xlfn._xlws.FILTER([1]График!$R$3:$R$89,([1]График!$F$3:$F$89=F18)*([1]График!$C$3:$C$89=C18))} -> #VALUE!
B19: ПАНЕЛИ KROKUS (max 200) | C19: ЦБ-00009132 | D19: CSVT KROKUS-PANEL 34 588x588х10 CRI80 3000 microprisma-opal IP54/IP20 чёрный 2800 | E19: ТД ЭЛЕКТРОТЕХМОНТАЖ, АО | F19: 00ЦБ-002421 | G19: Заказ клиента 00ЦБ-002421 от 17.03.2026 12:55:17 | H19: Рассрочка 60 к.дней | I19: Максимов А. И. | J19: 17.03.2026 12:55:17 | K19: 17.03.2026 | N19: 40 | P19: 40 | Q19: {=_xlfn._xlws.FILTER([1]График!$R$3:$R$89,([1]График!$F$3:$F$89=F19)*([1]График!$C$3:$C$89=C19))} -> #VALUE!
B20: ПАНЕЛИ KROKUS (max 200) | C20: ЦБ-00013422 | D20: CSVT KROKUS-PANEL 34 600х600х22 CRI80 5000 opal-sand IP54/IP40 белый E | E20: ЕВРОСТИЛЬ, ООО | F20: 00ЦБ-002447 | G20: Заказ клиента 00ЦБ-002447 от 18.03.2026 8:24:22 | H20: Предоплата 100% | I20: Вольная Т | J20: 18.03.2026 8:24:22 | K20: 23.03.2026 | N20: 8 | P20: 8 | Q20: {=_xlfn._xlws.FILTER([1]График!$R$3:$R$89,([1]График!$F$3:$F$89=F20)*([1]График!$C$3:$C$89=C20))} -> #VALUE!
B21: ПАНЕЛИ KROKUS (max 200) | C21: ЦБ000015157 | D21: CSVT KROKUS-PANEL 34 595x595х10 CRI80 5000 opal-sand IP54/IP20 белый | E21: РС, ООО (РУССКИЙ СВЕТ, ООО до 08/12/22 ЭЛЕКТРОСИСТЕМ, ООО) | F21: 00ЦБ-002567 | G21: Заказ клиента 00ЦБ-002567 от 19.03.2026 14:16:57 | H21: Рассрочка 45 к.дней | I21: _ФСК РС | J21: 19.03.2026 14:16:57 | K21: 20.03.2026 | N21: 10 | P21: 10 | Q21: {=_xlfn._xlws.FILTER([1]График!$R$3:$R$89,([1]График!$F$3:$F$89=F21)*([1]График!$C$3:$C$89=C21))} -> #VALUE!
B22: ПАНЕЛИ KROKUS (max 200) | C22: ЦБ000015161 | D22: CSVT KROKUS-PANEL 34 611x611х10 CRI80 5000 opal-sand IP54/IP20 белый | E22: ТД ЭЛЕКТРОТЕХМОНТАЖ, АО | F22: 00ЦБ-002673 | G22: Заказ клиента 00ЦБ-002673 от 23.03.2026 12:18:01 | H22: Рассрочка 60 к.дней | I22: Яворик Ю.В. | J22: 23.03.2026 12:18:01 | K22: 23.03.2026 | N22: 8 | P22: 8 | Q22: {=_xlfn._xlws.FILTER([1]График!$R$3:$R$89,([1]График!$F$3:$F$89=F22)*([1]График!$C$3:$C$89=C22))} -> #VALUE!
B23: ПАНЕЛИ KROKUS (max 200) | C23: ЦБ000015163 | D23: CSVT KROKUS-PANEL 34 595x595х10 CRI80 6500 opal-sand IP54/IP20 белый | E23: СВЕТКОНСАЛТ, ООО | F23: 00ЦБ-002206 | G23: Заказ клиента 00ЦБ-002206 от 11.03.2026 16:20:29 | H23: Предоплата 100% до передачи в производство | I23: Вольная Т | J23: 11.03.2026 16:20:29 | K23: 18.03.2026 | L23: 10 | N23: 17 | P23: 17 | Q23: {=_xlfn._xlws.FILTER([1]График!$R$3:$R$89,([1]График!$F$3:$F$89=F23)*([1]График!$C$3:$C$89=C23))} -> #VALUE!
B24: ПАНЕЛИ KROKUS (max 200) | C24: ЦБ000019312 | D24: CSVT KROKUS-PANEL 34 600x600х22 CRI80 4000 opal-sand IP54/IP20 белый | E24: ПРО-ПОТОЛКИ, ООО | F24: 00ЦБ-002444 | G24: Заказ клиента 00ЦБ-002444 от 17.03.2026 17:20:01 | H24: Предоплата 100% | I24: Курашкина Н.А. | J24: 17.03.2026 17:20:01 | K24: 19.03.2026 | L24: 72.5 | N24: 21 | P24: 21 | Q24: {=_xlfn._xlws.FILTER([1]График!$R$3:$R$89,([1]График!$F$3:$F$89=F24)*([1]График!$C$3:$C$89=C24))} -> #VALUE!
B25: ПАНЕЛИ KROKUS (max 200) | C25: ЦБ000019312 | D25: CSVT KROKUS-PANEL 34 600x600х22 CRI80 4000 opal-sand IP54/IP20 белый | E25: ТД ЭЛЕКТРОТЕХМОНТАЖ, АО | F25: 00ЦБ-002402 | G25: Заказ клиента 00ЦБ-002402 от 17.03.2026 10:45:14 | H25: Рассрочка 60 к.дней | I25: Яворик Ю.В. | J25: 17.03.2026 10:45:14 | K25: 17.03.2026 | L25: 72.5 | N25: 1 | P25: 1 | Q25: {=_xlfn._xlws.FILTER([1]График!$R$3:$R$89,([1]График!$F$3:$F$89=F25)*([1]График!$C$3:$C$89=C25))} -> #VALUE!
B26: ПАНЕЛИ SPARTA (200 max) | C26: ЦБ000012754 | D26: CSVT SPARTA-PANEL 34 595x595х18 CRI80 5000 opal-sand IP40 белый | E26: Смарт Лампс, ООО | F26: 00ЦБ-002491 | G26: Заказ клиента 00ЦБ-002491 от 18.03.2026 13:34:11 | H26: Предоплата 100% до передачи в производство | I26: Радзивилюк В.Ф. | J26: 18.03.2026 13:34:11 | K26: 19.03.2026 | N26: 20 | P26: 20 | Q26: {=_xlfn._xlws.FILTER([1]График!$R$3:$R$89,([1]График!$F$3:$F$89=F26)*([1]График!$C$3:$C$89=C26))} -> #VALUE!
B27: ПАНЕЛИ SPARTA (200 max) | C27: ЦБ000018778 | D27: CSVT SPARTA-PANEL-MULTI 34 595x595х18 CRI90 4000 opal-sand IP40 белый | E27: Смарт Лампс, ООО | F27: 00ЦБ-002491 | G27: Заказ клиента 00ЦБ-002491 от 18.03.2026 13:34:11 | H27: Предоплата 100% до передачи в производство | I27: Радзивилюк В.Ф. | J27: 18.03.2026 13:34:11 | K27: 19.03.2026 | N27: 35 | P27: 35 | Q27: {=_xlfn._xlws.FILTER([1]График!$R$3:$R$89,([1]График!$F$3:$F$89=F27)*([1]График!$C$3:$C$89=C27))} -> #VALUE!
B28: СВЕТИЛЬНИКИ AVRORA-40 (400 max) | C28: ЦБ-00010893 | D28: CSVT AVRORA-40-A 28 595х595х40 CRI80 4000 opal-sand IP20 белый армстронг с БАП на 3 часа LUXDATOR | E28: ПРО-ПОТОЛКИ, ООО | F28: 00ЦБ-002431 | G28: Заказ клиента 00ЦБ-002431 от 17.03.2026 15:49:35 | H28: Предоплата 100% | I28: Курашкина Н.А. | J28: 17.03.2026 15:49:35 | K28: 19.03.2026 | N28: 4 | P28: 4 | Q28: {=_xlfn._xlws.FILTER([1]График!$R$3:$R$89,([1]График!$F$3:$F$89=F28)*([1]График!$C$3:$C$89=C28))} -> 4
B29: СВЕТИЛЬНИКИ AVRORA-40 (400 max) | C29: ЦБ-00013767 | D29: KANT PRO G 35 595х595х40 CRI91 4000 opal-sand IP20 белый NATURAL COLOR | E29: МосЭнергоСервис, ООО | F29: 00ЦБ-002264 | G29: Заказ клиента 00ЦБ-002264 от 12.03.2026 15:46:43 | H29: Рассрочка 15 р.дней | I29: Гудилин К.И. | J29: 12.03.2026 15:46:43 | K29: 23.03.2026 | N29: 170 | P29: 170 | Q29: {=_xlfn._xlws.FILTER([1]График!$R$3:$R$89,([1]График!$F$3:$F$89=F29)*([1]График!$C$3:$C$89=C29))} -> 170
B30: СВЕТИЛЬНИКИ AVRORA-90 (IP20 550 max) | C30: РУ000003200 | D30: CSVT AVRORA 32 595x595х25 CRI80 4000 opal-sand IP20 белый армстронг | E30: ТД ЭЛЕКТРОТЕХМОНТАЖ, АО | F30: 00ЦБ-002530 | G30: Заказ клиента 00ЦБ-002530 от 19.03.2026 8:56:26 | H30: Рассрочка 60 к.дней | I30: Яворик Ю.В. | J30: 19.03.2026 8:56:26 | K30: 19.03.2026 | L30: 45 | N30: 5 | P30: 5 | Q30: {=_xlfn._xlws.FILTER([1]График!$R$3:$R$89,([1]График!$F$3:$F$89=F30)*([1]График!$C$3:$C$89=C30))} -> 5
B31: СВЕТИЛЬНИКИ AVRORA-90 (IP20 550 max) | C31: РУ000003200 | D31: CSVT AVRORA 32 595x595х25 CRI80 4000 opal-sand IP20 белый армстронг | E31: ТЕХДИЗАЙН, ООО (г.Москва) | F31: 00ЦБ-002580 | G31: Заказ клиента 00ЦБ-002580 от 19.03.2026 16:04:48 | H31: Предоплата 30% до передачи в производство, до отгрузки 70% | I31: Куртеев Н.А. | J31: 19.03.2026 16:04:48 | K31: 19.03.2026 | L31: 45 | M31: 30 | N31: 30 | P31: 30 | Q31: {=_xlfn._xlws.FILTER([1]График!$R$3:$R$89,([1]График!$F$3:$F$89=F31)*([1]График!$C$3:$C$89=C31))} -> 30 | U31: 30
B32: СВЕТИЛЬНИКИ AVRORA-90 (IP20 550 max) | C32: ЦБ-00004051 | D32: CSVT AVRORA 24 595х595х25 CRI90 4000 opal-sand IP20 белый армстронг ESCO-RS24 | E32: РС, ООО (РУССКИЙ СВЕТ, ООО до 08/12/22 ЭЛЕКТРОСИСТЕМ, ООО) | F32: 00ЦБ-002574 | G32: Заказ клиента 00ЦБ-002574 от 19.03.2026 14:53:37 | H32: Рассрочка 45 к.дней | I32: Юрина Инна | J32: 19.03.2026 14:53:37 | K32: 20.03.2026 | N32: 10 | P32: 10 | Q32: {=_xlfn._xlws.FILTER([1]График!$R$3:$R$89,([1]График!$F$3:$F$89=F32)*([1]График!$C$3:$C$89=C32))} -> 10
B33: СВЕТИЛЬНИКИ AVRORA-90 (IP20 550 max) | C33: ЦБ-00011322 | D33: Светильник ДВО 1004 СТАНДАРТ PRO 30Вт 4000К Ra>90 оп. IEK | E33: ИЭК ХОЛДИНГ, ПАО [ИЭК ХОЛДИНГ, АО до 10/03/26] | F33: 00ЦБ-002108 | G33: Заказ клиента 00ЦБ-002108 от 06.03.2026 14:10:14 | H33: Предоплата 50%, рассрочка 50% (30 к.д.) | I33: Куртеев Н.А. | J33: 06.03.2026 14:10:14 | K33: 17.03.2026 | L33: 6 | N33: 1000 | P33: 1000 | Q33: {=_xlfn._xlws.FILTER([1]График!$R$3:$R$89,([1]График!$F$3:$F$89=F33)*([1]График!$C$3:$C$89=C33))} -> 1000 | R33: 548
B34: СВЕТИЛЬНИКИ AVRORA-90 (IP20 550 max) | C34: ЦБ-00012466 | D34: Набор для сборки светильника RVE, номер 10 | E34: РВЭ, ООО (РУСВИТАЛЭЛЕКТРО) | F34: 00ЦБ-002521 | G34: Заказ клиента 00ЦБ-002521 от 18.03.2026 16:42:13 | H34: Предоплата 30% до передачи в производство, до отгрузки 70% | I34: Волков С.В. | J34: 18.03.2026 16:42:13 | K34: 23.03.2026 | L34: 828.5 | N34: 778 | P34: 778 | Q34: {=_xlfn._xlws.FILTER([1]График!$R$3:$R$89,([1]График!$F$3:$F$89=F34)*([1]График!$C$3:$C$89=C34))} -> 778 | T34: 286 | U34: 492
B35: СВЕТИЛЬНИКИ AVRORA-90 (IP20 550 max) | C35: ЦБ-00012466 | D35: Набор для сборки светильника RVE, номер 10 | E35: РВЭ, ООО (РУСВИТАЛЭЛЕКТРО) | F35: 00ЦБ-002472 | G35: Заказ клиента 00ЦБ-002472 от 18.03.2026 11:49:22 | H35: Предоплата 30% до передачи в производство, до отгрузки 70% | I35: Волков С.В. | J35: 18.03.2026 11:49:22 | K35: 23.03.2026 | L35: 828.5 | N35: 687 | P35: 687 | Q35: {=_xlfn._xlws.FILTER([1]График!$R$3:$R$89,([1]График!$F$3:$F$89=F35)*([1]График!$C$3:$C$89=C35))} -> 687 | S35: 451 | T35: 236
B36: СВЕТИЛЬНИКИ AVRORA-90 (IP20 550 max) | C36: ЦБ-00012467 | D36: Набор для сборки светильника RVE, номер 11 | E36: РВЭ, ООО (РУСВИТАЛЭЛЕКТРО) | F36: 00ЦБ-002468 | G36: Заказ клиента 00ЦБ-002468 от 18.03.2026 11:22:48 | H36: Предоплата 30% до передачи в производство, до отгрузки 70% | I36: Волков С.В. | J36: 18.03.2026 11:22:48 | K36: 23.03.2026 | N36: 59 | P36: 59 | Q36: {=_xlfn._xlws.FILTER([1]График!$R$3:$R$89,([1]График!$F$3:$F$89=F36)*([1]График!$C$3:$C$89=C36))} -> 59 | S36: 59
B37: СВЕТИЛЬНИКИ AVRORA-90 (IP20 550 max) | C37: ЦБ-00012467 | D37: Набор для сборки светильника RVE, номер 11 | E37: РВЭ, ООО (РУСВИТАЛЭЛЕКТРО) | F37: 00ЦБ-002521 | G37: Заказ клиента 00ЦБ-002521 от 18.03.2026 16:42:13 | H37: Предоплата 30% до передачи в производство, до отгрузки 70% | I37: Волков С.В. | J37: 18.03.2026 16:42:13 | K37: 23.03.2026 | N37: 20 | P37: 20 | Q37: {=_xlfn._xlws.FILTER([1]График!$R$3:$R$89,([1]График!$F$3:$F$89=F37)*([1]График!$C$3:$C$89=C37))} -> 20 | T37: 20
B38: СВЕТИЛЬНИКИ AVRORA-90 (IP20 550 max) | C38: ЦБ-00013201 | D38: Набор для сборки светильника RVE, номер 45 | E38: РВЭ, ООО (РУСВИТАЛЭЛЕКТРО) | F38: 00ЦБ-001371 | G38: Заказ клиента 00ЦБ-001371 от 16.02.2026 10:07:27 | H38: Предоплата 30% до передачи в производство, до отгрузки 70% | I38: Волков С.В. | J38: 16.02.2026 10:07:27 | K38: 26.02.2026 | N38: 12 | P38: 12 | Q38: {=_xlfn._xlws.FILTER([1]График!$R$3:$R$89,([1]График!$F$3:$F$89=F38)*([1]График!$C$3:$C$89=C38))} -> 12
B39: СВЕТИЛЬНИКИ AVRORA-90 (IP20 550 max) | C39: ЦБ-00013201 | D39: Набор для сборки светильника RVE, номер 45 | E39: РВЭ, ООО (РУСВИТАЛЭЛЕКТРО) | F39: 00ЦБ-002472 | G39: Заказ клиента 00ЦБ-002472 от 18.03.2026 11:49:22 | H39: Предоплата 30% до передачи в производство, до отгрузки 70% | I39: Волков С.В. | J39: 18.03.2026 11:49:22 | K39: 23.03.2026 | N39: 18 | P39: 18 | Q39: {=_xlfn._xlws.FILTER([1]График!$R$3:$R$89,([1]График!$F$3:$F$89=F39)*([1]График!$C$3:$C$89=C39))} -> 18 | S39: 18
B40: СВЕТИЛЬНИКИ AVRORA-90 (IP20 550 max) | C40: ЦБ-00013201 | D40: Набор для сборки светильника RVE, номер 45 | E40: РВЭ, ООО (РУСВИТАЛЭЛЕКТРО) | F40: 00ЦБ-001732 | G40: Заказ клиента 00ЦБ-001732 от 25.02.2026 14:20:13 | H40: Предоплата 30% до передачи в производство, до отгрузки 70% | I40: Волков С.В. | J40: 25.02.2026 14:20:13 | K40: 27.02.2026 | N40: 43 | P40: 43 | Q40: {=_xlfn._xlws.FILTER([1]График!$R$3:$R$89,([1]График!$F$3:$F$89=F40)*([1]График!$C$3:$C$89=C40))} -> 43
B41: СВЕТИЛЬНИКИ AVRORA-90 (IP20 550 max) | C41: ЦБ-00013201 | D41: Набор для сборки светильника RVE, номер 45 | E41: РВЭ, ООО (РУСВИТАЛЭЛЕКТРО) | F41: 00ЦБ-002521 | G41: Заказ клиента 00ЦБ-002521 от 18.03.2026 16:42:13 | H41: Предоплата 30% до передачи в производство, до отгрузки 70% | I41: Волков С.В. | J41: 18.03.2026 16:42:13 | K41: 23.03.2026 | N41: 8 | P41: 8 | Q41: {=_xlfn._xlws.FILTER([1]График!$R$3:$R$89,([1]График!$F$3:$F$89=F41)*([1]График!$C$3:$C$89=C41))} -> 8 | T41: 8
...
